Workbook

Sheet Summary
A1: Name | B1: Moto Track
A2: Current Period | B2: 7
A3: Final Period | B3: 18
A4: Periods per Year | B4: 52
A5: Playable Periods | B5: 18
A6: Initial Balance | B6: $700,000,000.00
A7: Interest Rate | B7: 12%
A8: Depreciation Cost | B8: $2,000,000.00
A9: Bank Balance | B9: $4,591,776,115.05

Sheet Transactions
A1: Period | B1: Inbound | C1: Concept | D1: Entity | E1: Period | F1: Outbound | G1: Concept | H1: Entity
A2: 0 | B2: 700000000 | C2: Game initial bank balance set
A3: 1 | B3: 1615384.6 | C3: Interest rate
A4: 1 | B4: 250000000 | C4: Sale orders of Store | D4: 🏪 MotoTrack Norte
A5: 1 | B5: 422000000 | C5: Sale orders of Store | D5: 🏪 MotoTrack Centro
A6: 1 | B6: 223000000 | C6: Sale orders of Store | D6: 🏪 MotoTrack Sur
E7: 1 | F7: 0 | G7: Depreciation of machines from Factory | H7: 🏭 MotoTrack
E8: 1 | F8: 3368169.2 | G8: Storage orders of Factory | H8: 🏭 MotoTrack
E9: 1 | F9: 169630000 | G9: Production orders of Factory | H9: 🏭 MotoTrack
E10: 1 | F10: 2000000 | G10: Transportation orders of Factory | H10: 🏭 MotoTrack
E11: 1 | F11: 0 | G11: Transportation orders of Raw material supplier | H11: 🚜 Proveedor Azul
E12: 1 | F12: 0 | G12: Supply orders of Raw material supplier | H12: 🚜 Proveedor Azul
E13: 1 | F13: 2000000 | G13: Transportation orders of Raw material supplier | H13: 🚜 Proveedor Amarillo
E14: 1 | F14: 544000000 | G14: Supply orders of Raw material supplier | H14: 🚜 Proveedor Amarillo
E15: 1 | F15: 0 | G15: Transportation orders of Raw material supplier | H15: 🚜 Proveedor Negro
E16: 1 | F16: 0 | G16: Supply orders of Raw material supplier | H16: 🚜 Proveedor Negro
E17: 1 | F17: 2358420 | G17: Storage orders of Distribution center | H17: 🚚 Cedi MotoTrack
E18: 1 | F18: 3000000 | G18: Transportation orders of Distribution center | H18: 🚚 Cedi MotoTrack
... E21: 1 | F21: 559040 | G21: Storage orders of Store | H21: 🏪 MotoTrack Sur
A22: 2 | B22: 2000025.5 | C22: Interest rate
A23: 2 | B23: 165000000 | C23: Sale orders of Store | D23: 🏪 MotoTrack Norte
A24: 2 | B24: 459000000 | C24: Sale orders of Store | D24: 🏪 MotoTrack Centro
A25: 2 | B25: 243000000 | C25: Sale orders of Store | D25: 🏪 MotoTrack Sur
E26: 2 | F26: 0 | G26: Depreciation of machines from Factory | H26: 🏭 MotoTrack
E27: 2 | F27: 3477857.9 | G27: Storage orders of Factory | H27: 🏭 MotoTrack
E28: 2 | F28: 167440000 | G28: Production orders of Factory | H28: 🏭 MotoTrack
E29: 2 | F29: 7000000 | G29: Transportation orders of Factory | H29: 🏭 MotoTrack
E30: 2 | F30: 1000000 | G30: Transportation orders of Raw material supplier | H30: 🚜 Proveedor Azul
E31: 2 | F31: 83500000 | G31: Supply orders of Raw material supplier | H31: 🚜 Proveedor Azul
E32: 2 | F32: 0 | G32: Transportation orders of Raw material supplier | H32: 🚜 Proveedor Amarillo
E33: 2 | F33: 0 | G33: Supply orders of Raw material supplier | H33: 🚜 Proveedor Amarillo
E34: 2 | F34: 0 | G34: Transportation orders of Raw material supplier | H34: 🚜 Proveedor Negro
E35: 2 | F35: 0 | G35: Supply orders of Raw material supplier | H35: 🚜 Proveedor Negro
E36: 2 | F36: 2354472 | G36: Storage orders of Distribution center | H36: 🚚 Cedi MotoTrack
E37: 2 | F37: 4000000 | G37: Transportation orders of Distribution center | H37: 🚚 Cedi MotoTrack
... E40: 2 | F40: 593536 | G40: Storage orders of Store | H40: 🏪 MotoTrack Sur
A41: 3 | B41: 3377911.1 | C41: Interest rate
A42: 3 | B42: 288000000 | C42: Sale orders of Store | D42: 🏪 MotoTrack Norte
A43: 3 | B43: 428000000 | C43: Sale orders of Store | D43: 🏪 MotoTrack Centro
A44: 3 | B44: 253000000 | C44: Sale orders of Store | D44: 🏪 MotoTrack Sur
...

Sheet Products & Materials
A1: Products
A2: Name | B2: Width | C2: Depth | D2: Height | E2: Weight
A3: MOTO | B3: 0.8 | C3: 2.2 | D3: 1.4 | E3: 1
A4: CUATRIMOTO | B4: 1.1 | C4: 1.2 | D4: 1.2 | E4: 1
A5: TRACTOR | B5: 1.2 | C5: 2.5 | D5: 1.3 | E5: 1
A7: Raw Materials
A8: Name | B8: Width | C8: Depth | D8: Height | E8: Weight
A9: CUARTO LADRILLO AZUL | B9: 0.11 | C9: 0.22 | D9: 0.08 | E9: 0.1
A10: MEDIO LADRILLO AZUL | B10: 0.22 | C10: 0.22 | D10: 0.08 | E10: 0.1
A11: LADRILLO COMPLETO AZUL | B11: 0.22 | C11: 0.44 | D11: 0.08 | E11: 0.1
A12: LADRILLO TRIANGULAR AZUL | B12: 0.22 | C12: 0.11 | D12: 0.15 | E12: 0.1
A13: DINTEL SIMPLE AMARILLO | B13: 0.22 | C13: 0.44 | D13: 0.08 | E13: 0.1
A14: DINTEL DOBLE AMARILLO | B14: 0.22 | C14: 0.88 | D14: 0.08 | E14: 0.1
A15: DINTEL TRIPLE AMARILLO | B15: 0.22 | C15: 1.32 | D15: 0.08 | E15: 0.1
A16: BLOQUE REDONDO SENCILLO AMARILLO | B16: 0.22 | C16: 0.22 | D16: 0.08 | E16: 0.1
A17: MEDIO BLOQUE REDONDO AMARILLO | B17: 0.11 | C17: 0.22 | D17: 0.08 | E17: 0.1
A18: BLOQUE REDONDO MACHO-MACHO AMARILLO | B18: 0.22 | C18: 0.22 | D18: 0.08 | E18: 0.1
A19: BLOQUE REDONDO HEMBRA-HEMBRA AMARILLO | B19: 0.22 | C19: 0.22 | D19: 0.08 | E19: 0.1
A20: CARRETE DE ESPIGAS AMARILLO | B20: 0.4 | C20: 0.4 | D20: 0.08 | E20: 0.1
... A37: EJE HEXAGONAL 10 CM | B37: 0.3 | C37: 0.3 | D37: 0.1 | E37: 1
A39: Product - Raw Material Relationship
A40: Product \ Raw Material | B40: CUARTO LADRILLO AZUL | C40: MEDIO LADRILLO AZUL | D40: LADRILLO COMPLETO AZUL | E40: LADRILLO TRIANGULAR AZUL | F40: DINTEL SIMPLE AMARILLO | G40: DINTEL DOBLE AMARILLO | H40: DINTEL TRIPLE AMARILLO | I40: BLOQUE REDONDO SENCILLO AMARILLO | J40: MEDIO BLOQUE REDONDO AMARILLO | K40: BLOQUE REDONDO MACHO-MACHO AMARILLO | L40: BLOQUE REDONDO HEMBRA-HEMBRA AMARILLO | M40: CARRETE DE ESPIGAS AMARILLO | N40: PIÑON GRANDE AMARILLO | O40: PIÑON PEQUEÑO AMARILLO | P40: PIÑON CONICO AMARILLO | Q40: VIGA SIMPLE GRIS | R40: VIGA DOBLE GRIS | S40: VIGA TRIPLE GRIS | T40: BLOQUE DE EJES NEGRO | U40: CILINDRO NEGRO | V40: COLUMNA NEGRA | W40: ESLABÓN DE ORUGA NEGRO | X40: PIN TRIPLE AZUL | Y40: PIN DOBLE AZUL | Z40: PIN SIMPLE AZUL | AA40: TOPE DE EJE AMARILLO | AB40: EJE HEXAGONAL 3.5 CM | AC40: EJE HEXAGONAL 6.5 CM | AD40: EJE HEXAGONAL 10 CM
A41: MOTO | B41: 1 | C41: 6 | D41: 8 | E41: 2 | F41: 1 | G41: 2 | I41: 7 | K41: 8 | L41: 3 | N41: 2 | Q41: 8 | R41: 2 | S41: 2 | T41: 3 | V41: 1 | W41: 28 | X41: 3 | Y41: 6 | Z41: 2 | AA41: 4 | AC41: 2
A42: CUATRIMOTO | B42: 2 | C42: 6 | D42: 8 | E42: 2 | F42: 3 | G42: 4 | J42: 2 | O42: 4 | Q42: 5 | T42: 4 | W42: 32 | X42: 4 | Y42: 4 | AA42: 4 | AD42: 2
A43: TRACTOR | B43: 2 | C43: 6 | D43: 8 | E43: 2 | F43: 3 | G43: 3 | H43: 3 | I43: 3 | J43: 2 | K43: 2 | L43: 2 | O43: 4 | Q43: 3 | T43: 4 | V43: 2 | W43: 40 | Z43: 4 | AA43: 4 | AD43: 2
A45: Product - Subproduct Relationship
A46: Parent \ Subproduct | B46: MOTO | C46: CUATRIMOTO | D46: TRACTOR
A47: MOTO
A48: CUATRIMOTO
A49: TRACTOR

Sheet Demand
A1: 🏪 MotoTrack Norte | F1: 🏪 MotoTrack Centro | K1: 🏪 MotoTrack Sur
A2: Turn | B2: MOTO | C2: CUATRIMOTO | D2: TRACTOR | F2: Turn | G2: MOTO | H2: CUATRIMOTO | I2: TRACTOR | K2: Turn | L2: MOTO | M2: CUATRIMOTO
A3: 1 | B3: 10 | C3: 8 | D3: 4 | F3: 1 | G3: 17 | H3: 4 | I3: 11 | K3: 1 | L3: 17 | M3: 6
A4: 2 | B4: 11 | C4: 5 | D4: 4 | F4: 2 | G4: 9 | H4: 9 | I4: 4 | K4: 2 | L4: 11 | M4: 10
A5: 3 | B5: 8 | C5: 7 | D5: 3 | F5: 3 | G5: 15 | H5: 8 | I5: 10 | K5: 3 | L5: 16 | M5: 12
A6: 4 | B6: 5 | C6: 2 | D6: 2 | F6: 4 | G6: 17 | H6: 9 | I6: 7 | K6: 4 | L6: 13 | M6: 8
A7: 5 | B7: 4 | C7: 0 | D7: 3 | F7: 5 | G7: 14 | H7: 6 | I7: 10 | K7: 5 | L7: 11 | M7: 7
A8: 6 | B8: 4 | C8: 2 | D8: 7 | F8: 6 | G8: 12 | H8: 5 | I8: 10 | K8: 6 | L8: 11 | M8: 10
A9: 7 | B9: 5 | C9: 9 | D9: 7 | F9: 7 | G9: 12 | H9: 6 | I9: 5 | K9: 7 | L9: 11 | M9: 10
A10: 8 | B10: 6 | C10: 7 | D10: 2 | F10: 8 | G10: 9 | H10: 4 | I10: 14 | K10: 8 | L10: 12 | M10: 8
A11: 9 | B11: 8 | C11: 7 | D11: 5 | F11: 9 | G11: 11 | H11: 8 | I11: 12 | K11: 9 | L11: 11 | M11: 8
A12: 10 | B12: 7 | C12: 8 | D12: 4 | F12: 10 | G12: 16 | H12: 7 | I12: 8 | K12: 10 | L12: 17 | M12: 10
A13: 11 | B13: 7 | C13: 12 | D13: 2 | F13: 11 | G13: 22 | H13: 8 | I13: 11 | K13: 11 | L13: 16 | M13: 9
A14: 12 | B14: 12 | C14: 0 | D14: 5 | F14: 12 | G14: 21 | H14: 9 | I14: 7 | K14: 12 | L14: 16 | M14: 12
... A216: 214 | B216: 12 | C216: 9 | D216: 6 | F216: 214 | G216: 28 | H216: 14 | I216: 13 | K216: 214 | L216: 18 | M216: 16

Sheet Transportation
A1: Origin | B1: Destiny | C1: Transportation Mean | D1: Fixed Price Per Turn | E1: Width | F1: Height | G1: Depth | H1: Capacity u3 | I1: Weight | J1: Quantity | K1: Turns To Destination
A2: 🚜 Proveedor Azul | B2: 🏭 MotoTrack | C2: truck | D2: 1000000 | E2: 3 | F2: 8 | G2: 3 | H2: 72 | I2: 100000 | J2: 1 | K2: 1
A3: 🚜 Proveedor Amarillo | B3: 🏭 MotoTrack | C3: truck | D3: 2000000 | E3: 3 | F3: 16 | G3: 3 | H3: 144 | I3: 100000 | J3: 1 | K3: 1
A4: 🚜 Proveedor Negro | B4: 🏭 MotoTrack | C4: ship | D4: 8000000 | E4: 9 | F4: 24 | G4: 9 | H4: 1944 | I4: 100000 | J4: 1 | K4: 4
A5: 🚜 Proveedor Negro | B5: 🏭 MotoTrack | C5: plane | D5: 1200000 | E5: 1 | F5: 3 | G5: 2 | H5: 6 | I5: 100000 | J5: 1 | K5: 1
A6: 🏭 MotoTrack | B6: 🚚 Cedi MotoTrack | C6: truck | D6: 1000000 | E6: 3 | F6: 16 | G6: 3 | H6: 144 | I6: 100000 | J6: 2 | K6: 1
A7: 🏭 MotoTrack | B7: 🏪 MotoTrack Norte | C7: truck | D7: 2500000 | E7: 3 | F7: 8 | G7: 3 | H7: 72 | I7: 100000 | J7: 2 | K7: 1
A8: 🚚 Cedi MotoTrack | B8: 🏪 MotoTrack Centro | C8: truck | D8: 1000000 | E8: 3 | F8: 8 | G8: 3 | H8: 72 | I8: 100000 | J8: 2 | K8: 1
A9: 🚚 Cedi MotoTrack | B9: 🏪 MotoTrack Sur | C9: truck | D9: 1000000 | E9: 3 | F9: 8 | G9: 3 | H9: 72 | I9: 100000 | J9: 2 | K9: 1

Sheet Production
A1: 🏭 MotoTrack
B3: Armar Base | C3: Armar Chasís | D3: Rueda - Oruga | E3: Asiento - Volante
A4: MOTO | B4: 20 | C4: 180 | D4: 295 | E4: 50
A5: CUATRIMOTO | B5: 20 | C5: 89 | D5: 235 | E5: 150
A6: TRACTOR | B6: 20 | C6: 245 | D6: 150 | E6: 100
A8: Availability | B8: 3000 | C8: 20000 | D8: 27000 | E8: 10000

Sheet Storage
A1: Type | B1: Name | C1: Internal Available Storage | D1: Internal Fixed Cost | E1: Internal Variable Cost | F1: External Fixed Cost | G1: External Cost per u3
A2: Factory | B2: 🏭 MotoTrack | C2: 2880 | D2: 1000000 | E2: 2500 | F2: 0 | G2: 5000
A3: Store | B3: 🏪 MotoTrack Norte | C3: 890 | D3: 500000 | E3: 7000 | F3: 0 | G3: 14000
A4: Store | B4: 🏪 MotoTrack Centro | C4: 720 | D4: 350000 | E4: 5000 | F4: 0 | G4: 10000
A5: Store | B5: 🏪 MotoTrack Sur | C5: 580 | D5: 200000 | E5: 4000 | F5: 0 | G5: 10000
A6: Distribution Center | B6: 🚚 Cedi MotoTrack | C6: 2304 | D6: 600000 | E6: 3000 | F6: 0 | G6: 8000

Sheet Costos
B2: Producto | C2: Proceso | D2: Minutos/unidad | E2: Costo/minuto | F2: MOD por proceso | K2: Materia prima | L2: Cantidad requerida | M2: Precio unitario | N2: Costo material | Q2: Producto | R2: MD
B3: Moto | C3: Armar Base | D3: =Production!B4 -> 20 | E3: 3000 | F3: =D3*E3 -> 60000 | K3: CUARTO LADRILLO AZUL | L3: =IFERROR(0+_xlfn.XLOOKUP(K3,'Products & Materials'!$B$40:$AD$40,'Products & Materials'!$B$41:$AD$41),0) -> 1 | M3: =_xlfn.XLOOKUP(K3,'Costo materia prima'!$D$3:$D$31,'Costo materia prima'!$E$3:$E$31) -> 10000 | N3: =IFERROR(L3*M3,0) -> 10000 | Q3: Moto | R3: 7000000
B4: Moto | C4: Armar Chasís | D4: =Production!C4 -> 180 | E4: 4000 | F4: =D4*E4 -> 720000 | K4: MEDIO LADRILLO AZUL | L4: =IFERROR(0+_xlfn.XLOOKUP(K4,'Products & Materials'!$B$40:$AD$40,'Products & Materials'!$B$41:$AD$41),0) -> 6 | M4: =_xlfn.XLOOKUP(K4,'Costo materia prima'!$D$3:$D$31,'Costo materia prima'!$E$3:$E$31) -> 20000 | N4: =IFERROR(L4*M4,0) -> 120000 | Q4: Cuatrimoto | R4: 9000000
B5: Moto | C5: Ruedas-Oruga | D5: =Production!D4 -> 295 | E5: 2500 | F5: =D5*E5 -> 737500 | K5: LADRILLO COMPLETO AZUL | L5: =IFERROR(0+_xlfn.XLOOKUP(K5,'Products & Materials'!$B$40:$AD$40,'Products & Materials'!$B$41:$AD$41),0) -> 8 | M5: =_xlfn.XLOOKUP(K5,'Costo materia prima'!$D$3:$D$31,'Costo materia prima'!$E$3:$E$31) -> 40000 | N5: =IFERROR(L5*M5,0) -> 320000 | Q5: Tractor | R5: 11000000
B6: Moto | C6: Asiento-Volante | D6: =Production!E4 -> 50 | E6: 2500 | F6: =D6*E6 -> 125000 | K6: LADRILLO TRIANGULAR AZUL | L6: =IFERROR(0+_xlfn.XLOOKUP(K6,'Products & Materials'!$B$40:$AD$40,'Products & Materials'!$B$41:$AD$41),0) -> 2 | M6: =_xlfn.XLOOKUP(K6,'Costo materia prima'!$D$3:$D$31,'Costo materia prima'!$E$3:$E$31) -> 25000 | N6: =IFERROR(L6*M6,0) -> 50000
E7: MOD Moto | F7: =SUM(F3:F6) -> 1642500 | K7: PIN TRIPLE AZUL | L7: =IFERROR(0+_xlfn.XLOOKUP(K7,'Products & Materials'!$B$40:$AD$40,'Products & Materials'!$B$41:$AD$41),0) -> 3 | M7: =_xlfn.XLOOKUP(K7,'Costo materia prima'!$D$3:$D$31,'Costo materia prima'!$E$3:$E$31) -> 40000 | N7: =IFERROR(L7*M7,0) -> 120000
K8: PIN DOBLE AZUL | L8: =IFERROR(0+_xlfn.XLOOKUP(K8,'Products & Materials'!$B$40:$AD$40,'Products & Materials'!$B$41:$AD$41),0) -> 6 | M8: =_xlfn.XLOOKUP(K8,'Costo materia prima'!$D$3:$D$31,'Costo materia prima'!$E$3:$E$31) -> 30000 | N8: =IFERROR(L8*M8,0) -> 180000
B9: Producto | C9: Proceso | D9: Minutos/unidad | E9: Costo/minuto | F9: MOD por proceso | K9: PIN SIMPLE AZUL | L9: =IFERROR(0+_xlfn.XLOOKUP(K9,'Products & Materials'!$B$40:$AD$40,'Products & Materials'!$B$41:$AD$41),0) -> 2 | M9: =_xlfn.XLOOKUP(K9,'Costo materia prima'!$D$3:$D$31,'Costo materia prima'!$E$3:$E$31) -> 20000 | N9: =IFERROR(L9*M9,0) -> 40000
B10: Cuatrimoto | C10: Armar Base | D10: =Production!B5 -> 20 | E10: 3000 | F10: =D10*E10 -> 60000 | K10: DINTEL SIMPLE AMARILLO | L10: =IFERROR(0+_xlfn.XLOOKUP(K10,'Products & Materials'!$B$40:$AD$40,'Products & Materials'!$B$41:$AD$41),0) -> 1 | M10: =_xlfn.XLOOKUP(K10,'Costo materia prima'!$D$3:$D$31,'Costo materia prima'!$E$3:$E$31) -> 20000 | N10: =IFERROR(L10*M10,0) -> 20000
B11: Cuatrimoto | C11: Armar Chasís | D11: =Production!C5 -> 89 | E11: 4000 | F11: =D11*E11 -> 356000 | K11: DINTEL DOBLE AMARILLO | L11: =IFERROR(0+_xlfn.XLOOKUP(K11,'Products & Materials'!$B$40:$AD$40,'Products & Materials'!$B$41:$AD$41),0) -> 2 | M11: =_xlfn.XLOOKUP(K11,'Costo materia prima'!$D$3:$D$31,'Costo materia prima'!$E$3:$E$31) -> 40000 | N11: =IFERROR(L11*M11,0) -> 80000
B12: Cuatrimoto | C12: Ruedas-Oruga | D12: =Production!D5 -> 235 | E12: 2500 | F12: =D12*E12 -> 587500 | K12: DINTEL TRIPLE AMARILLO | L12: =IFERROR(0+_xlfn.XLOOKUP(K12,'Products & Materials'!$B$40:$AD$40,'Products & Materials'!$B$41:$AD$41),0) -> 0 | M12: =_xlfn.XLOOKUP(K12,'Costo materia prima'!$D$3:$D$31,'Costo materia prima'!$E$3:$E$31) -> 100000 | N12: =IFERROR(L12*M12,0) -> 0
B13: Cuatrimoto | C13: Asiento-Volante | D13: =Production!E5 -> 150 | E13: 2500 | F13: =D13*E13 -> 375000 | K13: BLOQUE REDONDO SENCILLO AMARILLO | L13: =IFERROR(0+_xlfn.XLOOKUP(K13,'Products & Materials'!$B$40:$AD$40,'Products & Materials'!$B$41:$AD$41),0) -> 7 | M13: =_xlfn.XLOOKUP(K13,'Costo materia prima'!$D$3:$D$31,'Costo materia prima'!$E$3:$E$31) -> 50000 | N13: =IFERROR(L13*M13,0) -> 350000
E14: MOD Cuatrimoto | F14: =SUM(F10:F13) -> 1378500 | K14: MEDIO BLOQUE REDONDO AMARILLO | L14: =IFERROR(0+_xlfn.XLOOKUP(K14,'Products & Materials'!$B$40:$AD$40,'Products & Materials'!$B$41:$AD$41),0) -> 0 | M14: =_xlfn.XLOOKUP(K14,'Costo materia prima'!$D$3:$D$31,'Costo materia prima'!$E$3:$E$31) -> 40000 | N14: =IFERROR(L14*M14,0) -> 0
K15: BLOQUE REDONDO MACHO-MACHO AMARILLO | L15: =IFERROR(0+_xlfn.XLOOKUP(K15,'Products & Materials'!$B$40:$AD$40,'Products & Materials'!$B$41:$AD$41),0) -> 8 | M15: =_xlfn.XLOOKUP(K15,'Costo materia prima'!$D$3:$D$31,'Costo materia prima'!$E$3:$E$31) -> 50000 | N15: =IFERROR(L15*M15,0) -> 400000
B16: Producto | C16: Proceso | D16: Minutos/unidad | E16: Costo/minuto | F16: MOD por proceso | K16: BLOQUE REDONDO HEMBRA-HEMBRA AMARILLO | L16: =IFERROR(0+_xlfn.XLOOKUP(K16,'Products & Materials'!$B$40:$AD$40,'Products & Materials'!$B$41:$AD$41),0) -> 3 | M16: =_xlfn.XLOOKUP(K16,'Costo materia prima'!$D$3:$D$31,'Costo materia prima'!$E$3:$E$31) -> 50000 | N16: =IFERROR(L16*M16,0) -> 150000
B17: Tractor | C17: Armar Base | D17: =Production!B6 -> 20 | E17: 3000 | F17: =D17*E17 -> 60000 | K17: CARRETE DE ESPIGAS AMARILLO | L17: =IFERROR(0+_xlfn.XLOOKUP(K17,'Products & Materials'!$B$40:$AD$40,'Products & Materials'!$B$41:$AD$41),0) -> 0 | M17: =_xlfn.XLOOKUP(K17,'Costo materia prima'!$D$3:$D$31,'Costo materia prima'!$E$3:$E$31) -> 50000 | N17: =IFERROR(L17*M17,0) -> 0
B18: Tractor | C18: Armar Chasís | D18: =Production!C6 -> 245 | E18: 4000 | F18: =D18*E18 -> 980000 | K18: PIÑON GRANDE AMARILLO | L18: =IFERROR(0+_xlfn.XLOOKUP(K18,'Products & Materials'!$B$40:$AD$40,'Products & Materials'!$B$41:$AD$41),0) -> 2 | M18: =_xlfn.XLOOKUP(K18,'Costo materia prima'!$D$3:$D$31,'Costo materia prima'!$E$3:$E$31) -> 150000 | N18: =IFERROR(L18*M18,0) -> 300000
B19: Tractor | C19: Ruedas-Oruga | D19: =Production!D6 -> 150 | E19: 2500 | F19: =D19*E19 -> 375000 | K19: PIÑON PEQUEÑO AMARILLO | L19: =IFERROR(0+_xlfn.XLOOKUP(K19,'Products & Materials'!$B$40:$AD$40,'Products & Materials'!$B$41:$AD$41),0) -> 0 | M19: =_xlfn.XLOOKUP(K19,'Costo materia prima'!$D$3:$D$31,'Costo materia prima'!$E$3:$E$31) -> 50000 | N19: =IFERROR(L19*M19,0) -> 0
B20: Tractor | C20: Asiento-Volante | D20: =Production!E6 -> 100 | E20: 2500 | F20: =D20*E20 -> 250000 | K20: PIÑON CONICO AMARILLO | L20: =IFERROR(0+_xlfn.XLOOKUP(K20,'Products & Materials'!$B$40:$AD$40,'Products & Materials'!$B$41:$AD$41),0) -> 0 | M20: =_xlfn.XLOOKUP(K20,'Costo materia prima'!$D$3:$D$31,'Costo materia prima'!$E$3:$E$31) -> 50000 | N20: =IFERROR(L20*M20,0) -> 0
E21: MOD Tractor | F21: =SUM(F17:F20) -> 1665000 | K21: TOPE DE EJE AMARILLO | L21: =IFERROR(0+_xlfn.XLOOKUP(K21,'Products & Materials'!$B$40:$AD$40,'Products & Materials'!$B$41:$AD$41),0) -> 4 | M21: =_xlfn.XLOOKUP(K21,'Costo materia prima'!$D$3:$D$31,'Costo materia prima'!$E$3:$E$31) -> 5000 | N21: =IFERROR(L21*M21,0) -> 20000
K22: VIGA SIMPLE GRIS | L22: =IFERROR(0+_xlfn.XLOOKUP(K22,'Products & Materials'!$B$40:$AD$40,'Products & Materials'!$B$41:$AD$41),0) -> 8 | M22: =_xlfn.XLOOKUP(K22,'Costo materia prima'!$D$3:$D$31,'Costo materia prima'!$E$3:$E$31) -> 50000 | N22: =IFERROR(L22*M22,0) -> 400000
K23: VIGA DOBLE GRIS | L23: =IFERROR(0+_xlfn.XLOOKUP(K23,'Products & Materials'!$B$40:$AD$40,'Products & Materials'!$B$41:$AD$41),0) -> 2 | M23: =_xlfn.XLOOKUP(K23,'Costo materia prima'!$D$3:$D$31,'Costo materia prima'!$E$3:$E$31) -> 100000 | N23: =IFERROR(L23*M23,0) -> 200000
K24: VIGA TRIPLE GRIS | L24: =IFERROR(0+_xlfn.XLOOKUP(K24,'Products & Materials'!$B$40:$AD$40,'Products & Materials'!$B$41:$AD$41),0) -> 2 | M24: =_xlfn.XLOOKUP(K24,'Costo materia prima'!$D$3:$D$31,'Costo materia prima'!$E$3:$E$31) -> 150000 | N24: =IFERROR(L24*M24,0) -> 300000
K25: BLOQUE DE EJES NEGRO | L25: =IFERROR(0+_xlfn.XLOOKUP(K25,'Products & Materials'!$B$40:$AD$40,'Products & Materials'!$B$41:$AD$41),0) -> 3 | M25: =_xlfn.XLOOKUP(K25,'Costo materia prima'!$D$3:$D$31,'Costo materia prima'!$E$3:$E$31) -> 50000 | N25: =IFERROR(L25*M25,0) -> 150000
B26: Producto | C26: MD | D26: MOD | E26: Costo unitario MD + MOD | F26: Precio venta | K26: CILINDRO NEGRO | L26: =IFERROR(0+_xlfn.XLOOKUP(K26,'Products & Materials'!$B$40:$AD$40,'Products & Materials'!$B$41:$AD$41),0) -> 0 | M26: =_xlfn.XLOOKUP(K26,'Costo materia prima'!$D$3:$D$31,'Costo materia prima'!$E$3:$E$31) -> 5000 | N26: =IFERROR(L26*M26,0) -> 0
B27: Moto | C27: =N33 -> 3927000 | D27: =F7 -> 1642500 | E27: =C27+D27 -> 5569500 | F27: =R3 -> 7000000 | K27: COLUMNA NEGRA | L27: =IFERROR(0+_xlfn.XLOOKUP(K27,'Products & Materials'!$B$40:$AD$40,'Products & Materials'!$B$41:$AD$41),0) -> 1 | M27: =_xlfn.XLOOKUP(K27,'Costo materia prima'!$D$3:$D$31,'Costo materia prima'!$E$3:$E$31) -> 5000 | N27: =IFERROR(L27*M27,0) -> 5000
B28: Cuatrimoto | C28: =N66 -> 2988000 | D28: =F14 -> 1378500 | E28: =C28+D28 -> 4366500 | F28: =R4 -> 9000000 | K28: ESLABÓN DE ORUGA NEGRO | L28: =IFERROR(0+_xlfn.XLOOKUP(K28,'Products & Materials'!$B$40:$AD$40,'Products & Materials'!$B$41:$AD$41),0) -> 28 | M28: =_xlfn.XLOOKUP(K28,'Costo materia prima'!$D$3:$D$31,'Costo materia prima'!$E$3:$E$31) -> 4000 | N28: =IFERROR(L28*M28,0) -> 112000
B29: Tractor | C29: =N99 -> 3340000 | D29: =F21 -> 1665000 | E29: =C29+D29 -> 5005000 | F29: =R5 -> 11000000 | K29: EJE HEXAGONAL 3.5 CM | L29: =IFERROR(0+_xlfn.XLOOKUP(K29,'Products & Materials'!$B$40:$AD$40,'Products & Materials'!$B$41:$AD$41),0) -> 0 | M29: =_xlfn.XLOOKUP(K29,'Costo materia prima'!$D$3:$D$31,'Costo materia prima'!$E$3:$E$31) -> 300000 | N29: =IFERROR(L29*M29,0) -> 0
K30: EJE HEXAGONAL 6.5 CM | L30: =IFERROR(0+_xlfn.XLOOKUP(K30,'Products & Materials'!$B$40:$AD$40,'Products & Materials'!$B$41:$AD$41),0) -> 2 | M30: =_xlfn.XLOOKUP(K30,'Costo materia prima'!$D$3:$D$31,'Costo materia prima'!$E$3:$E$31) -> 300000 | N30: =IFERROR(L30*M30,0) -> 600000
K31: EJE HEXAGONAL 10 CM | L31: =IFERROR(0+_xlfn.XLOOKUP(K31,'Products & Materials'!$B$40:$AD$40,'Products & Materials'!$B$41:$AD$41),0) -> 0 | M31: =_xlfn.XLOOKUP(K31,'Costo materia prima'!$D$3:$D$31,'Costo materia prima'!$E$3:$E$31) -> 550000 | N31: =IFERROR(L31*M31,0) -> 0
K33: MD Moto | N33: =SUM(N3:N31) -> 3927000
K35: Materia prima | L35: Cantidad requerida | M35: Precio unitario | N35: Costo material
K36: CUARTO LADRILLO AZUL | L36: =IFERROR(0+_xlfn.XLOOKUP(K36,'Products & Materials'!$B$40:$AD$40,'Products & Materials'!$B$42:$AD$42),0) -> 2 | M36: =_xlfn.XLOOKUP(K36,'Costo materia prima'!$D$3:$D$31,'Costo materia prima'!$E$3:$E$31) -> 10000 | N36: =IFERROR(L36*M36,0) -> 20000
K37: MEDIO LADRILLO AZUL | L37: =IFERROR(0+_xlfn.XLOOKUP(K37,'Products & Materials'!$B$40:$AD$40,'Products & Materials'!$B$42:$AD$42),0) -> 6 | M37: =_xlfn.XLOOKUP(K37,'Costo materia prima'!$D$3:$D$31,'Costo materia prima'!$E$3:$E$31) -> 20000 | N37: =IFERROR(L37*M37,0) -> 120000
K38: LADRILLO COMPLETO AZUL | L38: =IFERROR(0+_xlfn.XLOOKUP(K38,'Products & Materials'!$B$40:$AD$40,'Products & Materials'!$B$42:$AD$42),0) -> 8 | M38: =_xlfn.XLOOKUP(K38,'Costo materia prima'!$D$3:$D$31,'Costo materia prima'!$E$3:$E$31) -> 40000 | N38: =IFERROR(L38*M38,0) -> 320000
K39: LADRILLO TRIANGULAR AZUL | L39: =IFERROR(0+_xlfn.XLOOKUP(K39,'Products & Materials'!$B$40:$AD$40,'Products & Materials'!$B$42:$AD$42),0) -> 2 | M39: =_xlfn.XLOOKUP(K39,'Costo materia prima'!$D$3:$D$31,'Costo materia prima'!$E$3:$E$31) -> 25000 | N39: =IFERROR(L39*M39,0) -> 50000
K40: PIN TRIPLE AZUL | L40: =IFERROR(0+_xlfn.XLOOKUP(K40,'Products & Materials'!$B$40:$AD$40,'Products & Materials'!$B$42:$AD$42),0) -> 4 | M40: =_xlfn.XLOOKUP(K40,'Costo materia prima'!$D$3:$D$31,'Costo materia prima'!$E$3:$E$31) -> 40000 | N40: =IFERROR(L40*M40,0) -> 160000
K41: PIN DOBLE AZUL | L41: =IFERROR(0+_xlfn.XLOOKUP(K41,'Products & Materials'!$B$40:$AD$40,'Products & Materials'!$B$42:$AD$42),0) -> 4 | M41: =_xlfn.XLOOKUP(K41,'Costo materia prima'!$D$3:$D$31,'Costo materia prima'!$E$3:$E$31) -> 30000 | N41: =IFERROR(L41*M41,0) -> 120000
K42: PIN SIMPLE AZUL | L42: =IFERROR(0+_xlfn.XLOOKUP(K42,'Products & Materials'!$B$40:$AD$40,'Products & Materials'!$B$42:$AD$42),0) -> 0 | M42: =_xlfn.XLOOKUP(K42,'Costo materia prima'!$D$3:$D$31,'Costo materia prima'!$E$3:$E$31) -> 20000 | N42: =IFERROR(L42*M42,0) -> 0
K43: DINTEL SIMPLE AMARILLO | L43: =IFERROR(0+_xlfn.XLOOKUP(K43,'Products & Materials'!$B$40:$AD$40,'Products & Materials'!$B$42:$AD$42),0) -> 3 | M43: =_xlfn.XLOOKUP(K43,'Costo materia prima'!$D$3:$D$31,'Costo materia prima'!$E$3:$E$31) -> 20000 | N43: =IFERROR(L43*M43,0) -> 60000
...

Sheet Costo materia prima
B2: ID | C2: Proveedor | D2: Materia prima | E2: Precio unitario
B3: 1 | C3: Azul | D3: CUARTO LADRILLO AZUL | E3: 10000
B4: 2 | C4: Azul | D4: MEDIO LADRILLO AZUL | E4: 20000
B5: 3 | C5: Azul | D5: LADRILLO COMPLETO AZUL | E5: 40000
B6: 4 | C6: Azul | D6: LADRILLO TRIANGULAR AZUL | E6: 25000
B7: 23 | C7: Azul | D7: PIN TRIPLE AZUL | E7: 40000
B8: 24 | C8: Azul | D8: PIN DOBLE AZUL | E8: 30000
B9: 25 | C9: Azul | D9: PIN SIMPLE AZUL | E9: 20000
B10: 5 | C10: Amarillo | D10: DINTEL SIMPLE AMARILLO | E10: 20000
B11: 6 | C11: Amarillo | D11: DINTEL DOBLE AMARILLO | E11: 40000
B12: 7 | C12: Amarillo | D12: DINTEL TRIPLE AMARILLO | E12: 100000
B13: 8 | C13: Amarillo | D13: BLOQUE REDONDO SENCILLO AMARILLO | E13: 50000
B14: 9 | C14: Amarillo | D14: MEDIO BLOQUE REDONDO AMARILLO | E14: 40000
... B31: 29 | C31: Negro | D31: EJE HEXAGONAL 10 CM | E31: 550000

Sheet Costos y Precios
A1: Producto | B1: MD | C1: MOD | D1: Costo unitario fabricación | E1: Precio venta
A2: Moto | B2: =Costos!C27 -> 3927000 | C2: =Costos!D27 -> 1642500 | D2: =Costos!E27 -> 5569500 | E2: =Costos!F27 -> 7000000
A3: Cuatrimoto | B3: =Costos!C28 -> 2988000 | C3: =Costos!D28 -> 1378500 | D3: =Costos!E28 -> 4366500 | E3: =Costos!F28 -> 9000000
A4: Tractor | B4: =Costos!C29 -> 3340000 | C4: =Costos!D29 -> 1665000 | D4: =Costos!E29 -> 5005000 | E4: =Costos!F29 -> 11000000
